Workbook

Sheet Base de Dados
A1: Desafio 01: Tabela de análise da falta de água no bairro da Vila Palmeira (São Luís - MA)
A2: Dados fictícios (simulação educacional). Os nomes das ruas são reais, mas as ocorrências são simuladas.
A3: Período de referência: 01/09/2026 a 30/09/2026. Frequência relatada = número de interrupções informadas para a rua nos últimos 30 dias.
A4: Nome: Antônio José Lobato Nogueira Trilha: Ciência De Dados
A5: ID do Registro | B5: Data da Ocorrência | C5: Rua ou Logradouro | D5: Horário de Início | E5: Horário de Retorno (data e hora) | F5: Duração da Interrupção (horas) | G5: Frequência Relatada (30 dias) | H5: Nível de Impacto | I5: Problemas Relatados | J5: Fonte do Registro | K5: Categoria do Problema
A6: 1 | B6: 46266 | C6: Rua Santa Júlia | D6: 0.069444444 | E6: 46266.368 | F6: =ROUND((E6-B6-D6)*24,2) -> 7.17 | G6: 7 | H6: Médio | I6: Água saindo fraca, demora para encher o balde | J6: Simulação educacional | K6: Pressão baixa
A7: 2 | B7: 46268 | C7: Rua Almirante Tamandaré | D7: 0.10416667 | E7: 46268.351 | F7: =ROUND((E7-B7-D7)*24,2) -> 5.92 | G7: 5 | H7: Médio | I7: Uso de água mineral para cozinhar | J7: Simulação educacional | K7: Preparo de alimentos
A8: 3 | B8: 46269 | C8: Rua do Ribeirão | D8: 0.29861111 | E8: 46269.528 | F8: =ROUND((E8-B8-D8)*24,2) -> 5.5 | G8: 5 | H8: Médio | I8: Higiene de crianças e idosos prejudicada | J8: Simulação educacional | K8: Higiene pessoal
A9: 4 | B9: 46269 | C9: Rua Boa Esperança | D9: 0.50694444 | E9: 46269.931 | F9: =ROUND((E9-B9-D9)*24,2) -> 10.17 | G9: 3 | H9: Médio | I9: Reservatório secou antes da água voltar | J9: Simulação educacional | K9: Armazenamento
A10: 5 | B10: 46270 | C10: Rua Daniel de La Touche | D10: 0.1875 | E10: 46270.34 | F10: =ROUND((E10-B10-D10)*24,2) -> 3.67 | G10: 4 | H10: Baixo | I10: Uso de água mineral para cozinhar | J10: Simulação educacional | K10: Preparo de alimentos
A11: 6 | B11: 46270 | C11: Rua Santa Júlia | D11: 0.45833333 | E11: 46270.997 | F11: =ROUND((E11-B11-D11)*24,2) -> 12.92 | G11: 7 | H11: Alto | I11: Água saindo fraca, demora para encher o balde | J11: Simulação educacional | K11: Pressão baixa
A12: 7 | B12: 46270 | C12: Rua Gustavo Barroso | D12: 0.625 | E12: 46271.014 | F12: =ROUND((E12-B12-D12)*24,2) -> 9.33 | G12: 2 | H12: Médio | I12: Impossibilidade de manter a higiene pessoal e da casa | J12: Simulação educacional | K12: Higiene pessoal
A13: 8 | B13: 46271 | C13: Rua Boa Esperança | D13: 0.35416667 | E13: 46271.771 | F13: =ROUND((E13-B13-D13)*24,2) -> 10 | G13: 3 | H13: Médio | I13: Roupa acumulada sem poder lavar | J13: Simulação educacional | K13: Atividades domésticas
A14: 9 | B14: 46271 | C14: Rua Daniel de La Touche | D14: 0.36111111 | E14: 46271.736 | F14: =ROUND((E14-B14-D14)*24,2) -> 9 | G14: 4 | H14: Médio | I14: Banhos adiados ou reduzidos | J14: Simulação educacional | K14: Higiene pessoal
A15: 10 | B15: 46271 | C15: Rua Almirante Tamandaré | D15: 0.90972222 | E15: 46272.444 | F15: =ROUND((E15-B15-D15)*24,2) -> 12.83 | G15: 6 | H15: Alto | I15: Reservatório secou antes da água voltar | J15: Simulação educacional | K15: Armazenamento
A16: 11 | B16: 46276 | C16: Rua dos Eucaliptos | D16: 0.45138889 | E16: 46276.986 | F16: =ROUND((E16-B16-D16)*24,2) -> 12.83 | G16: 6 | H16: Alto | I16: Caixa d'água esvaziada, rotina familiar interrompida | J16: Simulação educacional | K16: Armazenamento
A17: 12 | B17: 46276 | C17: Rua Almirante Tamandaré | D17: 0.86458333 | E17: 46277.642 | F17: =ROUND((E17-B17-D17)*24,2) -> 18.67 | G17: 3 | H17: Alto | I17: Precisou pegar água com vizinho | J17: Simulação educacional | K17: Armazenamento
... A45: 40 | B45: 46295 | C45: Rua Santa Júlia | D45: 0.96527778 | E45: 46296.33 | F45: =ROUND((E45-B45-D45)*24,2) -> 8.75 | G45: 6 | H45: Alto | I45: Água saindo fraca, demora para encher o balde | J45: Simulação educacional | K45: Pressão baixa
E46: Média / Total | F46: =AVERAGE(F6:F45) -> 8.07975 | G46: =SUM(G6:G45) -> 172

Sheet Resumo da Análise
B1: Resumo da Análise: Falta de água na Vila Palmeira
B2: São Luís - MA | Setembro de 2026 | Dados fictícios (simulação educacional)
B4: Indicadores gerais
B5: Indicador | C5: Valor
B6: Total de registros | C6: =COUNTA('Base de Dados'!$A$6:$A$45) -> 40
B7: Duração média (h) | C7: =AVERAGE('Base de Dados'!$F$6:$F$45) -> 8.07975
B8: Maior duração (h) | C8: =MAX('Base de Dados'!$F$6:$F$45) -> 23.33
B9: Menor duração (h) | C9: =MIN('Base de Dados'!$F$6:$F$45) -> 1.5
B10: Registros de impacto Alto | C10: =COUNTIF('Base de Dados'!$H$6:$H$45,"Alto") -> 12
B11: Interrupções de 12 h ou mais | C11: =COUNTIF('Base de Dados'!$F$6:$F$45,">=12") -> 7
B14: 1. Registros por nível de impacto
B15: Nível de impacto | C15: Registros | D15: % do total
B16: Baixo | C16: =COUNTIF('Base de Dados'!$H$6:$H$45,B16) -> 12 | D16: =C16/$C$19 -> 0.3
B17: Médio | C17: =COUNTIF('Base de Dados'!$H$6:$H$45,B17) -> 16 | D17: =C17/$C$19 -> 0.4
B18: Alto | C18: =COUNTIF('Base de Dados'!$H$6:$H$45,B18) -> 12 | D18: =C18/$C$19 -> 0.3
B19: Total | C19: =SUM(C16:C18) -> 40 | D19: =SUM(D16:D18) -> 1
B30: 2. Registros por rua
B31: Rua | C31: Registros | D31: % do total
B32: Rua do Ribeirão | C32: =COUNTIF('Base de Dados'!$C$6:$C$45,B32) -> 3 | D32: =C32/$C$42 -> 0.075
B33: Rua Primeiro de Maio | C33: =COUNTIF('Base de Dados'!$C$6:$C$45,B33) -> 4 | D33: =C33/$C$42 -> 0.1
B34: Rua Santa Júlia | C34: =COUNTIF('Base de Dados'!$C$6:$C$45,B34) -> 7 | D34: =C34/$C$42 -> 0.175
B35: Rua dos Eucaliptos | C35: =COUNTIF('Base de Dados'!$C$6:$C$45,B35) -> 5 | D35: =C35/$C$42 -> 0.125
B36: Avenida Sarney Filho | C36: =COUNTIF('Base de Dados'!$C$6:$C$45,B36) -> 2 | D36: =C36/$C$42 -> 0.05
B37: Rua Almirante Tamandaré | C37: =COUNTIF('Base de Dados'!$C$6:$C$45,B37) -> 5 | D37: =C37/$C$42 -> 0.125
B38: Rua Gustavo Barroso | C38: =COUNTIF('Base de Dados'!$C$6:$C$45,B38) -> 3 | D38: =C38/$C$42 -> 0.075
B39: Rua Boa Esperança | C39: =COUNTIF('Base de Dados'!$C$6:$C$45,B39) -> 4 | D39: =C39/$C$42 -> 0.1
B40: Rua Daniel de La Touche | C40: =COUNTIF('Base de Dados'!$C$6:$C$45,B40) -> 4 | D40: =C40/$C$42 -> 0.1
B41: Rua do Progresso | C41: =COUNTIF('Base de Dados'!$C$6:$C$45,B41) -> 3 | D41: =C41/$C$42 -> 0.075
B42: Total | C42: =SUM(C32:C41) -> 40 | D42: =SUM(D32:D41) -> 1
B48: 3. Duração média das interrupções por rua (horas)
B49: Rua | C49: Duração média (h) | D49: Média geral (h)
B50: Rua do Ribeirão | C50: =AVERAGEIF('Base de Dados'!$C$6:$C$45,B50,'Base de Dados'!$F$6:$F$45) -> 4.1133333 | D50: =$C$7 -> 8.07975
B51: Rua Primeiro de Maio | C51: =AVERAGEIF('Base de Dados'!$C$6:$C$45,B51,'Base de Dados'!$F$6:$F$45) -> 5.065 | D51: =$C$7 -> 8.07975
B52: Rua Santa Júlia | C52: =AVERAGEIF('Base de Dados'!$C$6:$C$45,B52,'Base de Dados'!$F$6:$F$45) -> 10.821429 | D52: =$C$7 -> 8.07975
B53: Rua dos Eucaliptos | C53: =AVERAGEIF('Base de Dados'!$C$6:$C$45,B53,'Base de Dados'!$F$6:$F$45) -> 9.834 | D53: =$C$7 -> 8.07975
B54: Avenida Sarney Filho | C54: =AVERAGEIF('Base de Dados'!$C$6:$C$45,B54,'Base de Dados'!$F$6:$F$45) -> 2.585 | D54: =$C$7 -> 8.07975
B55: Rua Almirante Tamandaré | C55: =AVERAGEIF('Base de Dados'!$C$6:$C$45,B55,'Base de Dados'!$F$6:$F$45) -> 10.534 | D55: =$C$7 -> 8.07975
B56: Rua Gustavo Barroso | C56: =AVERAGEIF('Base de Dados'!$C$6:$C$45,B56,'Base de Dados'!$F$6:$F$45) -> 6.7466667 | D56: =$C$7 -> 8.07975
B57: Rua Boa Esperança | C57: =AVERAGEIF('Base de Dados'!$C$6:$C$45,B57,'Base de Dados'!$F$6:$F$45) -> 7.5 | D57: =$C$7 -> 8.07975
B58: Rua Daniel de La Touche | C58: =AVERAGEIF('Base de Dados'!$C$6:$C$45,B58,'Base de Dados'!$F$6:$F$45) -> 10.6675 | D58: =$C$7 -> 8.07975
...

Sheet Metodologia
A1: Metodologia
A3: Objetivo | B3: Praticar o tratamento e a análise de dados usando como tema a falta de água no bairro Vila Palmeira, em São Luís (MA).
A4: Origem dos dados | B4: Simulação educacional. Nenhuma ocorrência corresponde a um registro real.
A5: Período | B5: 01/09/2026 a 30/09/2026, dividido em 5 semanas na aba Resumo da Análise.
A6: Ruas | B6: Os nomes das ruas são reais (conferidos em sites de CEP), mas a distribuição das ocorrências entre elas é inventada.
A7: Unidade de análise | B7: Cada linha da Base de Dados é uma interrupção no fornecimento de água.
A8: Duração | B8: Duração (h) = (data e hora de retorno - data - horário de início) x 24, arredondada em 2 casas.
A9: Nível de impacto | B9: Baixo, Médio ou Alto, escolhido pela lista suspensa. Considerou-se principalmente a duração e a frequência relatada.
A10: Categorias | B10: Os problemas relatados foram agrupados em 5 categorias: Higiene pessoal, Armazenamento, Atividades domésticas, Preparo de alimentos e Pressão baixa.
A11: Formatação | B11: Cabeçalho congelado, filtros na tabela, cores para o nível de impacto e bloqueio de frequência negativa.
A12: Resumo | B12: As tabelas e gráficos da aba Resumo da Análise usam fórmulas (COUNTIF, AVERAGEIF, COUNTIFS, SUM, AVERAGE, MAX e MIN) e se atualizam se a Base de Dados for alterada.
A13: Privacidade | B13: Não há nomes de moradores, números de casas ou outros dados pessoais.
A14: Limitações | B14: Como os dados são simulados, os resultados não mostram quais ruas realmente sofrem mais com a falta de água.
